//You are given a project to demonstrate the uses of the throws, throw, finally, and custom exceptions in Java.
public class P16_throw {
    static void fun()
    {
        try
        {
            throw new NullPointerException("demo");
        }
        catch(NullPointerException e)
        {
            System.out.println("Caught inside fun().");
            throw e; // rethrowing the exception
        }
    }

    public static void main(String[] args)
    {
        try
        {
            fun();
        }
        catch(NullPointerException e)
        {
            System.out.println("Caught in main.");
        }
    }
}
